<?xml version="1.0" encoding="utf-8"?>
<!-- This URDF was automatically created by SolidWorks to URDF Exporter! Originally created by Stephen Brawner (brawner@gmail.com) 
     Commit Version: 1.6.0-4-g7f85cfe  Build Version: 1.6.7995.38578
     For more information, please see http://wiki.ros.org/sw_urdf_exporter -->
<robot name="XBot-L">
  <mujoco>
    <compiler meshdir="../meshes/" balanceinertia="true" discardvisual="false" />
  </mujoco>
  <!-- <link name="odom">
  </link> -->

  <!-- <joint name="ob" type="revolute">
     <origin xyz="0 0 0" rpy="0 0 0" />
    <parent link="odom" />
    <child link="base_link" />
    <axis xyz="0 1 0" />
    <limit lower="-0.4647" upper="0.5" effort="350" velocity="4" />
    <dynamics damping="0.1" friction="0.1" />
  </joint>   -->

  <link name="base_link">
    <inertial>
      <origin xyz="-0.080697 8.52E-06 -0.087154" rpy="0 0 0" />
      <mass value="8.7757" />
      <inertia ixx="0.13466" ixy="-0.00013895" ixz="-0.0099766" iyy="0.037377" iyz="-9.094E-05" izz="0.13912" />
    </inertial>
    <visual>
      <origin xyz="0 0 0" rpy="0 0 0" />
      <geometry>
        <mesh filename="../meshes/base_link.STL" />
      </geometry>
      <material name="">
        <color rgba="0.75294 0.75294 0.75294 1" />
      </material>
    </visual>
    <collision>
      <origin xyz="0 0 0" rpy="0 0 0" />
      <geometry>
        <box size="0.5 0.2 0.2"/>
      </geometry>
    </collision>

    <!-- <collision>
      <origin xyz="0 0 0" rpy="0 0 0" />
      <geometry>
        <mesh filename="../meshes/base_link.STL" />
      </geometry>
    </collision> -->
  </link>

  <!--left leg  %%%%%%%%%%%%%%%%%%%%%%%%%%%%%%%%%%%%%%%%%%%%%%%%%%%%%%%%%%%%%%%%%%%%%%%%%%%%%%%%%%%%%%%%%%%%%%%%%%%%-->
  <link name="leg_l1_link">
    <inertial>
      <origin xyz="0.050925 -8.452E-05 -0.005854" rpy="0 0 0" />
      <mass value="2.2605" />
      <inertia ixx="0.003557" ixy="4.7E-07" ixz="0.00016875" iyy="0.0038455" iyz="5.86E-06" izz="0.0044064" />
    </inertial>
    <visual>
      <origin xyz="0 0 0" rpy="0 0 0" />
      <geometry>
        <mesh filename="../meshes/leg_l1_link.STL" />
      </geometry>
      <material name="">
        <color rgba="0.75294 0.75294 0.75294 1" />
      </material>
    </visual>
    <!-- <collision>
      <origin xyz="0 0 0" rpy="0 0 0" />
      <geometry>
        <mesh filename="../meshes/left_leg_roll_link.STL" />
      </geometry>
    </collision> -->
  </link>
  <joint name="leg_l1_joint" type="revolute">
    <origin xyz="-0.0666 0.14 -0.109" rpy="0 0 0" />
    <parent link="base_link" />
    <child link="leg_l1_link" />
    <axis xyz="1 0 0" />
    <limit lower="-0.087" upper="1.57" effort="119" velocity="2.51" />
    <dynamics damping="12.736" friction="2.736" />
  </joint>
  <link name="leg_l2_link">
    <inertial>
      <origin xyz="-0.0039083 -0.0011634 -0.026864" rpy="0 0 0" />
      <mass value="0.67611" />
      <inertia ixx="0.0012933" ixy="3.08E-06" ixz="-1.89E-05" iyy="0.0003687" iyz="-3.6E-06" izz="0.0014339" />
    </inertial>
    <visual>
      <origin xyz="0 0 0" rpy="0 0 0" />
      <geometry>
        <mesh filename="../meshes/leg_l2_link.STL" />
      </geometry>
      <material name="">
        <color rgba="0.75294 0.75294 0.75294 1" />
      </material>
    </visual>
    <!-- <collision>
      <origin xyz="0 0 0" rpy="0 0 0" />
      <geometry>
        <mesh filename="../meshes/left_leg_yaw_link.STL" />
      </geometry>
    </collision> -->
  </link>
  <joint name="leg_l2_joint" type="revolute">
    <origin xyz="0.0621 0 -0.044" rpy="0 0 0" />
    <parent link="leg_l1_link" />
    <child link="leg_l2_link" />
    <axis xyz="0 0 1" />
    <limit lower="-1.57" upper="1.57" effort="120" velocity="4.18" />
    <dynamics damping="3.747" friction="3.424" />
  </joint>
  <link name="leg_l3_link">
    <inertial>
      <origin xyz="-0.018592 -2.02E-05 -0.20901" rpy="0 0 0" />
      <mass value="9.4927" />
      <inertia ixx="0.11116" ixy="3.94E-06" ixz="0.0066322" iyy="0.13566" iyz="-4.984E-05" izz="0.037578" />
    </inertial>
    <visual>
      <origin xyz="0 0 0" rpy="0 0 0" />
      <geometry>
        <mesh filename="../meshes/leg_l3_link.STL" />
      </geometry>
      <material name="">
        <color rgba="0.75294 0.75294 0.75294 1" />
      </material>
    </visual>
    <collision>
      <origin xyz="0 0 -0.17" rpy="0 0 0" />
      <geometry>
        <box size="0.08 0.08 0.25" />
      </geometry>
    </collision>
  </link>
  <joint name="leg_l3_joint" type="revolute">
    <origin xyz="0 0 -0.0325" rpy="0 0 0" />
    <parent link="leg_l2_link" />
    <child link="leg_l3_link" />
    <axis xyz="0 1 0" />
    <limit lower="-1.22" upper="0.17" effort="200" velocity="5.23" />
    <dynamics damping="1.714" friction="3.823" />
  </joint>
  <link name="leg_l4_link">
    <inertial>
      <origin xyz="-0.0060469 -6.993E-05 -0.15852" rpy="0 0 0" />
      <mass value="6.5464" />
      <inertia ixx="0.057889" ixy="1.539E-05" ixz="-0.0065366" iyy="0.053034" iyz="0.00012154" izz="0.014966" />
    </inertial>
    <visual>
      <origin xyz="0 0 0" rpy="0 0 0" />
      <geometry>
        <mesh filename="../meshes/leg_l4_link.STL" />
      </geometry>
      <material name="">
        <color rgba="0.75294 0.75294 0.75294 1" />
      </material>
    </visual>
    <collision>
      <origin xyz="0 0 -0.18" rpy="0 0 0" />
      <geometry>
        <box size="0.05 0.05 0.28" />
      </geometry>
    </collision>
  </link>
  <joint name="leg_l4_joint" type="revolute">
    <origin xyz="0 0 -0.43" rpy="0 0 0" />
    <parent link="leg_l3_link" />
    <child link="leg_l4_link" />
    <axis xyz="0 1 0" />
    <limit lower="-0.174" upper="1.3" effort="240" velocity="4.36" />
    <dynamics damping="7.74" friction="5.659" />
  </joint>
  <link name="leg_l5_link">
    <inertial>
      <origin xyz="0 0 0" rpy="0 0 0" />
      <mass value="0.091432" />
      <inertia ixx="1.185E-05" ixy="0" ixz="0" iyy="1.185E-05" iyz="0" izz="1.616E-05" />
    </inertial>
    <visual>
      <origin xyz="0 0 0" rpy="0 0 0" />
      <geometry>
        <mesh filename="../meshes/leg_l5_link.STL" />
      </geometry>
      <material name="">
        <color rgba="0.75294 0.75294 0.75294 1" />
      </material>
    </visual>
    <!-- <collision>
      <origin xyz="0 0 0" rpy="0 0 0" />
      <geometry>
        <mesh filename="../meshes/left_ankle_pitch_link.STL" />
      </geometry>
    </collision> -->
  </link>
  <joint name="leg_l5_joint" type="revolute">
    <origin xyz="0 0 -0.36" rpy="0 0 0" />
    <parent link="leg_l4_link" />
    <child link="leg_l5_link" />
    <axis xyz="0 1 0" />
    <limit lower="-0.697" upper="0.348" effort="130" velocity="4.36" />
    <dynamics damping="10.068" friction="8.573" />
  </joint>
  <link name="leg_l6_link">
    <inertial>
      <origin xyz="0.02265382 0 -0.03519545" rpy="0 0 0" />
      <mass value="0.6688682" />
      <inertia ixx="0.00065567" ixy="7E-08" ixz="0.00016569" iyy="0.00396496" iyz="-4E-08" izz="0.00442875" />
    </inertial>
    <visual>
      <origin xyz="0 0 0" rpy="0 0 0" />
      <geometry>
        <mesh filename="../meshes/leg_l6_link.STL" />
      </geometry>
      <material name="">
        <color rgba="0.75294 0.75294 0.75294 1" />
      </material>
    </visual>


    <collision>
    <origin xyz="0.04 0.0 -0.045" rpy="0 0 0" />
    <geometry>
        <box size="0.26 0.091 0.018" />
    </geometry>
    </collision> 
  </link>
  <joint name="leg_l6_joint" type="revolute">
    <origin xyz="0 0 0" rpy="0 0 0" />
    <parent link="leg_l5_link" />
    <child link="leg_l6_link" />
    <axis xyz="1 0 0" />
    <limit lower="-0.26" upper="0.26" effort="130" velocity="6.54" />
    <dynamics damping="8.4" friction="3.4" />
  </joint>




























  <!--right leg %%%%%%%%%%%%%%%%%%%%%%%%%%%%%%%%%%%%%%%%%%%%%%%%%%%%%%%%%%%%%%%%%%%%%%%%%%%%%%%%%%%%%%%%%%%%%%%%%%%-->
  <link name="leg_r1_link">
    <inertial>
      <origin xyz="0.05092541 -8.452E-05 -0.00585399" rpy="0 0 0" />
      <mass value="2.26050125" />
      <inertia ixx="0.00355697" ixy="4.7E-07" ixz="0.00016875" iyy="0.00384548" iyz="5.86E-06" izz="0.00440643" />
    </inertial>
    <visual>
      <origin xyz="0 0 0" rpy="0 0 0" />
      <geometry>
        <mesh filename="../meshes/leg_r1_link.STL" />
      </geometry>
      <material name="">
        <color rgba="0.75294 0.75294 0.75294 1" />
      </material>
    </visual>
    <!-- <collision>
      <origin xyz="0 0 0" rpy="0 0 0" />
      <geometry>
        <mesh filename="../meshes/right_leg_roll_link.STL" />
      </geometry>
    </collision> -->
  </link>
  <joint name="leg_r1_joint" type="revolute">
    <origin xyz="-0.0666 -0.14 -0.109" rpy="0 0 0" />
    <parent link="base_link" />
    <child link="leg_r1_link" />
    <axis xyz="1 0 0" />
    <limit lower="-1.57" upper="0.087" effort="119" velocity="2.5" />
    <dynamics damping="12.736" friction="2.736" />
  </joint>
  <link name="leg_r2_link">
    <inertial>
      <origin xyz="-0.00390825 -0.00116338 -0.02686431" rpy="0 0 0" />
      <mass value="0.6761071" />
      <inertia ixx="0.00129332" ixy="3.08E-06" ixz="-1.89E-05" iyy="0.0003687" iyz="-3.6E-06" izz="0.00143388" />
    </inertial>
    <visual>
      <origin xyz="0 0 0" rpy="0 0 0" />
      <geometry>
        <mesh filename="../meshes/leg_r2_link.STL" />
      </geometry>
      <material name="">
        <color rgba="0.75294 0.75294 0.75294 1" />
      </material>
    </visual>
    <!-- <collision>
      <origin xyz="0 0 0" rpy="0 0 0" />
      <geometry>
        <mesh filename="../meshes/right_leg_yaw_link.STL" />
      </geometry>
    </collision> -->
  </link>
  <joint name="leg_r2_joint" type="revolute">
    <origin xyz="0.0621 0 -0.044" rpy="0 0 0" />
    <parent link="leg_r1_link" />
    <child link="leg_r2_link" />
    <axis xyz="0 0 1" />
    <limit lower="-1.57" upper="1.57" effort="120" velocity="4.18" />
    <dynamics damping="3.747" friction="3.424" />
  </joint>
  <link name="leg_r3_link">
    <inertial>
      <origin xyz="-0.01859241 -2.02E-05 -0.20901058" rpy="0 0 0" />
      <mass value="9.49271851" />
      <inertia ixx="0.11115744" ixy="3.94E-06" ixz="0.0066322" iyy="0.13566381" iyz="-4.984E-05" izz="0.03757752" />
    </inertial>
    <visual>
      <origin xyz="0 0 0" rpy="0 0 0" />
      <geometry>
        <mesh filename="../meshes/leg_r3_link.STL" />
      </geometry>
      <material name="">
        <color rgba="0.75294 0.75294 0.75294 1" />
      </material>
    </visual>
    <collision>
      <origin xyz="0 0 -0.17" rpy="0 0 0" />
      <geometry>
        <box size="0.08 0.08 0.25" />
      </geometry>
    </collision>
  </link>
  <joint name="leg_r3_joint" type="revolute">
    <origin xyz="0 0 -0.0325" rpy="0 0 0" />
    <parent link="leg_r2_link" />
    <child link="leg_r3_link" />
    <axis xyz="0 1 0" />
    <limit lower="-1.22" upper="0.17" effort="200" velocity="5.23" />
    <dynamics damping="1.714" friction="3.823" />
  </joint>
  <link name="leg_r4_link">
    <inertial>
      <origin xyz="-0.00604687 -6.993E-05 -0.1585234" rpy="0 0 0" />
      <mass value="6.54635421" />
      <inertia ixx="0.05788881" ixy="1.539E-05" ixz="-0.00653656" iyy="0.05303365" iyz="0.00012154" izz="0.01496565" />
    </inertial>
    <visual>
      <origin xyz="0 0 0" rpy="0 0 0" />
      <geometry>
        <mesh filename="../meshes/leg_r4_link.STL" />
      </geometry>
      <material name="">
        <color rgba="0.75294 0.75294 0.75294 1" />
      </material>
    </visual>
    <collision>
      <origin xyz="0 0 -0.18" rpy="0 0 0" />
      <geometry>
        <box size="0.05 0.05 0.28" />
      </geometry>
    </collision>
  </link>
  <joint name="leg_r4_joint" type="revolute">
    <origin xyz="0 0 -0.43" rpy="0 0 0" />
    <parent link="leg_r3_link" />
    <child link="leg_r4_link" />
    <axis xyz="0 1 0" />
    <limit lower="-0.174" upper="1.3" effort="240" velocity="4.36" />
    <dynamics damping="7.74" friction="5.659" />
  </joint>
  <link name="leg_r5_link">
    <inertial>
      <origin xyz="0 0 0" rpy="0 0 0" />
      <mass value="0.09143186" />
      <inertia ixx="1.185E-05" ixy="0" ixz="0" iyy="1.185E-05" iyz="0" izz="1.616E-05" />
    </inertial>
    <visual>
      <origin xyz="0 0 0" rpy="0 0 0" />
      <geometry>
        <mesh filename="../meshes/leg_r5_link.STL" />
      </geometry>
      <material name="">
        <color rgba="0.752941176470588 0.752941176470588 0.752941176470588 1" />
      </material>
    </visual>
    <!-- <collision>
      <origin xyz="0 0 0" rpy="0 0 0" />
      <geometry>
        <mesh filename="../meshes/right_ankle_pitch_link.STL" />
      </geometry>
    </collision> -->
  </link>
  <joint name="leg_r5_joint" type="revolute">
    <origin xyz="0 0 -0.36" rpy="0 0 0" />
    <parent link="leg_r4_link" />
    <child link="leg_r5_link" />
    <axis xyz="0 1 0" />
    <limit lower="-0.697" upper="0.348" effort="130" velocity="4.36" />
    <dynamics damping="10.068" friction="8.573" />
  </joint>


  <link name="leg_r6_link">
    <inertial>
      <origin xyz="0.02265382 0 -0.03519545" rpy="0 0 0" />
      <mass value="0.6688682" />
      <inertia ixx="0.00065567" ixy="7E-08" ixz="0.00016569" iyy="0.00396496" iyz="-4E-08" izz="0.00442875" />
    </inertial>
    <visual>
      <origin xyz="0 0 0" rpy="0 0 0" />
      <geometry>
        <mesh filename="../meshes/leg_r6_link.STL" />
      </geometry>
      <material name="">
        <color rgba="0.75294 0.75294 0.75294 1" />
      </material>
    </visual>
    <collision>
    <origin xyz="0.04 0.0 -0.045" rpy="0 0 0" />
    <geometry>
        <box size="0.26 0.091 0.018" />
    </geometry>
    </collision> 
  </link>



  <joint name="leg_r6_joint" type="revolute">
    <origin xyz="0 0 0" rpy="0 0 0" />
    <parent link="leg_r5_link" />
    <child link="leg_r6_link" />
    <axis xyz="1 0 0" />
    <limit lower="-0.26" upper="0.26" effort="130" velocity="6.54" />
    <dynamics damping="8.4" friction="3.4" />
  </joint>

  <!-- 新增 foot_link -->
  <link name="left_foot_front_link" />
  <!-- <link name="left_foot_front_link">
    <visual>
      <origin xyz="0 0 0"/>
      <geometry>
        <sphere radius="0.005"/>
      </geometry>
      <material name="red">
        <color rgba="1 0 0 1"/>
      </material>
    </visual>
  </link> -->

  <joint name="left_foot_front_joint" type="fixed" dont_collapse="true">
    <origin xyz="0.15 0 -0.058" rpy="0 0 0" />
    <parent link="leg_l6_link" />
    <child link="left_foot_front_link" />
  </joint>

  <link name="left_foot_mid_link" />
  <!-- <link name="left_foot_mid_link">
    <visual>
      <origin xyz="0 0 0"/>
      <geometry>
        <sphere radius="0.005"/>
      </geometry>
      <material name="green">
        <color rgba="0 1 0 1"/>
      </material>
    </visual>
  </link> -->

  <joint name="left_foot_mid_joint" type="fixed" dont_collapse="true">
    <origin xyz="0.0 0 -0.058" rpy="0 0 0" />
    <parent link="leg_l6_link" />
    <child link="left_foot_mid_link" />
  </joint>

  <link name="left_foot_hind_link" />
  <!-- <link name="left_foot_hind_link">
    <visual>
      <origin xyz="0 0 0"/>
      <geometry>
        <sphere radius="0.005"/>
      </geometry>
      <material name="blue">
        <color rgba="0 0 1 1"/>
      </material>
    </visual>
  </link> -->

  <joint name="left_foot_hind_joint" type="fixed" dont_collapse="true">
    <origin xyz="-0.095 0 -0.058" rpy="0 0 0" />
    <parent link="leg_l6_link" />
    <child link="left_foot_hind_link" />
  </joint>

  <link name="right_foot_front_link" />
  <!-- <link name="right_foot_front_link">
    <visual>
      <origin xyz="0 0 0"/>
      <geometry>
        <sphere radius="0.005"/>
      </geometry>
      <material name="cyan">
        <color rgba="0 1 1 1"/>
      </material>
    </visual>
  </link> -->

  <joint name="right_foot_front_joint" type="fixed" dont_collapse="true">
    <origin xyz="0.15 0 -0.058" rpy="0 0 0" />
    <parent link="leg_r6_link" />
    <child link="right_foot_front_link" />
  </joint>

  <link name="right_foot_mid_link" />
  <!-- <link name="right_foot_mid_link">
    <visual>
      <origin xyz="0 0 0"/>
      <geometry>
        <sphere radius="0.005"/>
      </geometry>
      <material name="magenta">
        <color rgba="1 0 1 1"/>
      </material>
    </visual>
  </link> -->

  <joint name="right_foot_mid_joint" type="fixed" dont_collapse="true">
    <origin xyz="0.0 0 -0.058" rpy="0 0 0" />
    <parent link="leg_r6_link" />
    <child link="right_foot_mid_link" />
  </joint>

  <link name="right_foot_hind_link" />
  <!-- <link name="right_foot_hind_link">
    <visual>
      <origin xyz="0 0 0"/>
      <geometry>
        <sphere radius="0.005"/>
      </geometry>
      <material name="yellow">
        <color rgba="1 1 0 1"/>
      </material>
    </visual>
  </link> -->

  <joint name="right_foot_hind_joint" type="fixed" dont_collapse="true">
    <origin xyz="-0.095 0 -0.058" rpy="0 0 0" />
    <parent link="leg_r6_link" />
    <child link="right_foot_hind_link" />
  </joint>


</robot>