<mujoco model="XBot-L">
  <compiler angle="radian" meshdir="../meshes/" eulerseq="zyx"/>
  <option timestep='0.001' iterations='50' solver='PGS' gravity='0 0 -9.81'>
    <!--flag sensornoise="enable" frictionloss="enable"/-->
  </option>
  <size njmax="500" nconmax="100" />

  <visual>
    <quality shadowsize='4096'/>
    <map znear='0.05'/>
  </visual>

  <default>
    <joint limited='true'/>
    <motor ctrllimited='true'/>
    <default class='joint1'>
        <joint  damping="12.736" frictionloss="2.736" armature="0.05"/>
    </default> 
    <default class='joint2'>
    	<joint  damping="3.747" frictionloss="3.424" armature="0.01"/>
    </default>         
    <default class='joint3'>
        <joint  damping="1.714" frictionloss="3.823" armature="0.01"/>
    </default> 
      <default class='joint4'>
        <joint damping="7.74" frictionloss="5.659" armature="0.2"/>
    </default> 
    <default class='joint5'>
        <joint  damping="10.068" frictionloss="8.573" armature="2"/>
    </default> 
    <default class='joint6'>
        <joint  damping="8.4" frictionloss="3.4" armature="2"/>
    </default> 
  </default>

  <asset>
    <mesh name="base_link" file="base_link.STL"/>
    <mesh name="leg_l1_link" file="leg_l1_link.STL"/>
    <mesh name="leg_l2_link" file="leg_l2_link.STL"/>
    <mesh name="leg_l3_link" file="leg_l3_link.STL"/>
    <mesh name="leg_l4_link" file="leg_l4_link.STL"/>
    <mesh name="leg_l5_link" file="leg_l5_link.STL"/>
    <mesh name="leg_l6_link" file="leg_l6_link.STL"/>
    <mesh name="leg_r1_link" file="leg_r1_link.STL"/>
    <mesh name="leg_r2_link" file="leg_r2_link.STL"/>
    <mesh name="leg_r3_link" file="leg_r3_link.STL"/>
    <mesh name="leg_r4_link" file="leg_r4_link.STL"/>
    <mesh name="leg_r5_link" file="leg_r5_link.STL"/>
    <mesh name="leg_r6_link" file="leg_r6_link.STL"/>
  </asset>
  <worldbody>


    <body name="base_link" pos="0 0 1.025" quat="1.0 0 0.0 0">      <!--zero position: posz=1.14   -->
      <inertial mass="8.7757" pos="-0.080697 8.52e-06 -0.087154" quat="0.306415586175932 0.305756549202002 -0.637993039948727 0.63685736405064" diaginertia="0.147112792900926 0.126667515419065 0.0373766916800093" />

      <site name='imu' size='0.01' pos='-0.10 0.0 0.0'/>
      <geom type="mesh" contype="0" conaffinity="0" group="1" density="0" rgba="0.75294 0.75294 0.75294 1" mesh="base_link"/>
      <geom size="0.2 0.1 0.1" type="box" rgba="0 0 0 0"/>

      <joint name="dummy_to_base_link" type="free" pos="0.0 0.0 0.0" axis="0.0 0.0 1.0" range="0.0 0.0" damping="0.0" stiffness="0.0" armature="0.0" frictionloss="0.0" />
      <geom mesh="base_link" type="mesh" contype="0" conaffinity="0" pos="0.0 0.0 0.0" quat="1.0 0.0 0.0 0.0" rgba="0.75294 0.75294 0.75294 1.0" />
      <geom rgba="0 0.7 0.3 0.1" type="box" pos="0.0 0.0 0.0" quat="1.0 0.0 0.0 0.0" size="0.25 0.1 0.1" contype="1" conaffinity="1" friction="1.0 0.005 0.0001" />
      <body name="leg_l1_link" pos="-0.0666 0.14 -0.109">
        <inertial mass="2.2605" pos="0.050925 -8.452e-05 -0.005854" quat="0.0023693877295224 0.770698735937438 0.0044314320717536 0.637179885774826" diaginertia="0.0044387549970758 0.0038454437112697 0.0035247012916544" />
        <joint name="leg_l1_joint" type="hinge" pos="0.0 0.0 0.0" axis="1.0 0.0 0.0" range="-0.087 1.57" class="joint1" />
        <geom mesh="leg_l1_link" type="mesh" contype="0" conaffinity="0" pos="0.0 0.0 0.0" quat="1.0 0.0 0.0 0.0" rgba="0.75294 0.75294 0.75294 1.0" />
        <body name="leg_l2_link" pos="0.0621 0.0 -0.044">
          <inertial mass="0.67611" pos="-0.0039083 -0.0011634 -0.026864" quat="0.464454591155867 0.467737992017537 -0.531866529159276 0.531621198540565" diaginertia="0.0014364110702823 0.0012908109383973 0.0003686779913202" />
          <joint name="leg_l2_joint" type="hinge" pos="0.0 0.0 0.0" axis="0.0 0.0 1.0" range="-1.57 1.57" class="joint2" />
          <geom mesh="leg_l2_link" type="mesh" contype="0" conaffinity="0" pos="0.0 0.0 0.0" quat="1.0 0.0 0.0 0.0" rgba="0.75294 0.75294 0.75294 1.0" />
          <body name="leg_l3_link" pos="0.0 0.0 -0.0325">
            <inertial mass="9.4927" pos="-0.018592 -2.02e-05 -0.20901" quat="0.706404369467941 -0.0316972191833732 -0.03133864775274 0.706403597279681" diaginertia="0.135660025339505 0.111753004025958 0.0369849706345375" />
            <joint name="leg_l3_joint" type="hinge" pos="0.0 0.0 0.0" axis="0.0 1.0 0.0" range="-1.22 0.17" class="joint3" />
            <geom mesh="leg_l3_link" type="mesh" contype="0" conaffinity="0" pos="0.0 0.0 0.0" quat="1.0 0.0 0.0 0.0" rgba="0.75294 0.75294 0.75294 1.0" />
            <geom rgba="0 0.7 0.3 0.1" type="box" pos="0.0 0.0 -0.17" quat="1.0 0.0 0.0 0.0" size="0.04 0.04 0.125" contype="1" conaffinity="1" friction="1.0 0.005 0.0001" />
            <body name="leg_l4_link" pos="0.0 0.0 -0.43">
              <inertial mass="6.5464" pos="-0.0060469 -6.993e-05 -0.15852" quat="0.99726848654997 0.0015473323246807 0.0738447861751561 -0.0003450387729108" diaginertia="0.0588623652116306 0.0530343830148565 0.0139922517735129" />
              <joint name="leg_l4_joint" type="hinge" pos="0.0 0.0 0.0" axis="0.0 1.0 0.0" range="-0.174 1.3" class="joint4" />
              <geom mesh="leg_l4_link" type="mesh" contype="0" conaffinity="0" pos="0.0 0.0 0.0" quat="1.0 0.0 0.0 0.0" rgba="0.75294 0.75294 0.75294 1.0" />
              <geom rgba="0 0.7 0.3 0.1" type="box" pos="0.0 0.0 -0.18" quat="1.0 0.0 0.0 0.0" size="0.025 0.025 0.14" contype="1" conaffinity="1" friction="1.0 0.005 0.0001" />
              <body name="leg_l5_link" pos="0.0 0.0 -0.36">
                <inertial mass="0.091432" pos="0.0 0.0 0.0" quat="0.500000000000001 0.500000000000001 -0.500000000000001 0.500000000000001" diaginertia="1.616e-05 1.185e-05 1.185e-05" />
                <joint name="leg_l5_joint" type="hinge" pos="0.0 0.0 0.0" axis="0.0 1.0 0.0" range="-0.697 0.348" class="joint5" />
                <geom mesh="leg_l5_link" type="mesh" contype="0" conaffinity="0" pos="0.0 0.0 0.0" quat="1.0 0.0 0.0 0.0" rgba="0.75294 0.75294 0.75294 1.0" />
                <body name="leg_l6_link" pos="0.0 0.0 0.0">
                  <inertial mass="0.668868" pos="0.0226538 0 -0.0351955" quat="-1.92727e-05 0.722422 -3.57655e-05 0.691452" diaginertia="0.00443601 0.00396496 0.000648408" />
                  <joint name="leg_l6_joint" type="hinge" pos="0.0 0.0 0.0" axis="1.0 0.0 0.0" range="-0.26 0.26" class="joint6" />
                  <geom mesh="leg_l6_link" type="mesh" contype="0" conaffinity="0" pos="0.0 0.0 0.0" quat="1.0 0.0 0.0 0.0" rgba="0.75294 0.75294 0.75294 1.0" />
                  <geom rgba="0 0.7 0.3 0.1" type="box" pos="0.04 0.0 -0.045" quat="1.0 0.0 0.0 0.0" size="0.13 0.0455 0.009" contype="1" conaffinity="1" friction="1.0 0.005 0.0001" />

                  <!-- 添加力传感器 -->
                  <geom name="l6_patch" type="box" size="0.11 0.0455 0.0013" pos="0.025  0 -0.0537" group="2" rgba="1 0 0 0.5" contype="1" conaffinity="1" density="0.00001" mass="0"/>
                  <site name="l6_force_patch" pos="0.025  0 -0.0537" size="0.001" rgba="1 0 0 1"/>

                </body>
              </body>
            </body>
          </body>
        </body>
      </body>
      <body name="leg_r1_link" pos="-0.0666 -0.14 -0.109">
        <inertial mass="2.26050125" pos="0.05092541 -8.452e-05 -0.00585399" quat="0.0023692695105264 0.77069487627464 0.0044310305147276 0.63718455742005" diaginertia="0.0044387828725242 0.0038454237154481 0.0035246734120275" />
        <joint name="leg_r1_joint" type="hinge" pos="0.0 0.0 0.0" axis="1.0 0.0 0.0" range="-1.57 0.087" class="joint1" />
        <geom mesh="leg_r1_link" type="mesh" contype="0" conaffinity="0" pos="0.0 0.0 0.0" quat="1.0 0.0 0.0 0.0" rgba="0.75294 0.75294 0.75294 1.0" />
        <body name="leg_r2_link" pos="0.0621 0.0 -0.044">
          <inertial mass="0.6761071" pos="-0.00390825 -0.00116338 -0.02686431" quat="0.464445108324014 0.467728496245257 -0.531874909764205 0.531629453207182" diaginertia="0.0014363917572497 0.0012908302514377 0.0003686779913125" />
          <joint name="leg_r2_joint" type="hinge" pos="0.0 0.0 0.0" axis="0.0 0.0 1.0" range="-1.57 1.57" class="joint2" />
          <geom mesh="leg_r2_link" type="mesh" contype="0" conaffinity="0" pos="0.0 0.0 0.0" quat="1.0 0.0 0.0 0.0" rgba="0.75294 0.75294 0.75294 1.0" />
          <body name="leg_r3_link" pos="0.0 0.0 -0.0325">
            <inertial mass="9.49271851" pos="-0.01859241 -2.02e-05 -0.20901058" quat="0.70640433064962 -0.0316980829746236 -0.0313395271905482 0.706403558322486" diaginertia="0.1356638353384 0.111750460523418 0.0369844741381813" />
            <joint name="leg_r3_joint" type="hinge" pos="0.0 0.0 0.0" axis="0.0 1.0 0.0" range="-1.22 0.17" class="joint3" />
            <geom mesh="leg_r3_link" type="mesh" contype="0" conaffinity="0" pos="0.0 0.0 0.0" quat="1.0 0.0 0.0 0.0" rgba="0.75294 0.75294 0.75294 1.0" />
            <geom rgba="0 0.7 0.3 0.1" type="box" pos="0.0 0.0 -0.17" quat="1.0 0.0 0.0 0.0" size="0.04 0.04 0.125" contype="1" conaffinity="1" friction="1.0 0.005 0.0001" />
            <body name="leg_r4_link" pos="0.0 0.0 -0.43">
              <inertial mass="6.54635421" pos="-0.00604687 -6.993e-05 -0.1585234" quat="0.997268537222902 0.0015473347010516 0.0738441018864359 -0.0003450176821328" diaginertia="0.0588621600862714 0.0530340330152136 0.013991916898515" />
              <joint name="leg_r4_joint" type="hinge" pos="0.0 0.0 0.0" axis="0.0 1.0 0.0" range="-0.174 1.3" class="joint4" />
              <geom mesh="leg_r4_link" type="mesh" contype="0" conaffinity="0" pos="0.0 0.0 0.0" quat="1.0 0.0 0.0 0.0" rgba="0.75294 0.75294 0.75294 1.0" />
              <geom rgba="0 0.7 0.3 0.1" type="box" pos="0.0 0.0 -0.18" quat="1.0 0.0 0.0 0.0" size="0.025 0.025 0.14" contype="1" conaffinity="1" friction="1.0 0.005 0.0001" />
              <body name="leg_r5_link" pos="0.0 0.0 -0.36">
                <inertial mass="0.09143186" pos="0.0 0.0 0.0" quat="0.500000000000001 0.500000000000001 -0.500000000000001 0.500000000000001" diaginertia="1.616e-05 1.185e-05 1.185e-05" />
                <joint name="leg_r5_joint" type="hinge" pos="0.0 0.0 0.0" axis="0.0 1.0 0.0" range="-0.697 0.348" class="joint5" />
                <geom mesh="leg_r5_link" type="mesh" contype="0" conaffinity="0" pos="0.0 0.0 0.0" quat="1.0 0.0 0.0 0.0" rgba="0.7529412 0.7529412 0.7529412 1.0" />
                <body name="leg_r6_link" pos="0.0 0.0 0.0">
                  <inertial mass="0.668868" pos="0.0226538 0 -0.0351955" quat="-1.92727e-05 0.722422 -3.57655e-05 0.691452" diaginertia="0.00443601 0.00396496 0.000648408" />
                  <joint name="leg_r6_joint" type="hinge" pos="0.0 0.0 0.0" axis="1.0 0.0 0.0" range="-0.26 0.26" class="joint6" />
                  <geom mesh="leg_r6_link" type="mesh" contype="0" conaffinity="0" pos="0.0 0.0 0.0" quat="1.0 0.0 0.0 0.0" rgba="0.75294 0.75294 0.75294 1.0" />
                  <geom rgba="0 0.7 0.3 0.1" type="box" pos="0.04 0.0 -0.045" quat="1.0 0.0 0.0 0.0" size="0.13 0.0455 0.009" contype="1" conaffinity="1" friction="1.0 0.005 0.0001" />

                  <!-- 添加力传感器 -->
                  <geom name="r6_patch" type="box" size="0.11 0.0455 0.0013" pos="0.025  0 -0.0537" group="2" rgba="1 0 0 0.5" contype="1" conaffinity="1" density="0.00001" mass="0"/>
                  <site name="r6_force_patch" pos="0.025  0 -0.0537" size="0.001" rgba="1 0 0 1"/>
                </body>
              </body>
            </body>
          </body>
        </body>
      </body>
    </body>
  </worldbody>

  <actuator>
    <motor name="leg_l1_joint_motor" joint="leg_l1_joint" ctrlrange="-119.0 119.0" />
    <motor name="leg_l2_joint_motor" joint="leg_l2_joint" ctrlrange="-120.0 120.0" />
    <motor name="leg_l3_joint_motor" joint="leg_l3_joint" ctrlrange="-200.0 100.0" />
    <motor name="leg_l4_joint_motor" joint="leg_l4_joint" ctrlrange="-240.0 140.0" />
    <motor name="leg_l5_joint_motor" joint="leg_l5_joint" ctrlrange="-130.0 130.0" />
    <motor name="leg_l6_joint_motor" joint="leg_l6_joint" ctrlrange="-130.0 130.0" />
    <motor name="leg_r1_joint_motor" joint="leg_r1_joint" ctrlrange="-119.0 119.0" />
    <motor name="leg_r2_joint_motor" joint="leg_r2_joint" ctrlrange="-120.0 120.0" />
    <motor name="leg_r3_joint_motor" joint="leg_r3_joint" ctrlrange="-200.0 100.0" />
    <motor name="leg_r4_joint_motor" joint="leg_r4_joint" ctrlrange="-240.0 140.0" />
    <motor name="leg_r5_joint_motor" joint="leg_r5_joint" ctrlrange="-130.0 130.0" />
    <motor name="leg_r6_joint_motor" joint="leg_r6_joint" ctrlrange="-130.0 130.0" />
  </actuator>
  <visual>
    <headlight diffuse="0.6 0.6 0.6" ambient="0.3 0.3 0.3" specular="0 0 0" />
    <rgba haze="0.15 0.25 0.35 1" />
    <global azimuth="160" elevation="-20" />
  </visual>

  <sensor>
    <framequat name='body-orientation' objtype='site' noise='0.001' objname='imu'/>
    <framepos name='body-linear-pos' objtype='site' noise='0.001' objname='imu'/>
    <gyro name='body-angular-velocity' site='imu' noise='0.005' cutoff='34.9'/>
    <velocimeter name='body-linear-vel' site='imu' noise='0.001' cutoff='30'/>
    <accelerometer name='body-linear-acceleration' site='imu' noise='0.005' cutoff='157'/>
    <magnetometer name='magnetometer' site='imu'/>

    <force name="l_feet_force" site="l6_force_patch"/>
    <force name="r_feet_force" site="r6_force_patch"/>

  </sensor>
</mujoco>